## **1. Response Code data and dataType:**
```python
    url = "https://api.freeapi.app/api/v1/public/randomusers/user/random"
    response = requests.get(url)  
    data = response.json()
    print(type(data))
```
`requests.get(url)` ka response aik `requests.Response` object hota hai. Is object ka `.json()` method use karke, hum JSON data ko Python dictionary ya list mein convert kar sakte hain. Agar API ka response JSON format mein ho, to `response.json()` aik dictionary ya list return karega. Agar response JSON format mein na ho, to `.json()` method `json.decoder.JSONDecodeError` raise karega.

Aam tor par, agar API se JSON response milta hai, to `response.json()` se milne wala data ka type `dict` ya `list` hota hai. Iska pata lagane ke liye, aap `type()` function use kar sakte hain, jaise:


```python
data = response.json()
print(type(data))
```


Yeh code aapko data ke type ke bare mein batayega. 


-----------------
----------------
------------------

## **2. raise Exception code breakdown:**
Python mein, agar program execution ke doran koi error ya ghair-mamooli surat-e-haal paish aaye, to isay "exception" kehte hain. "Exception" ka urdu mein matlab hai "ÿßÿ≥ÿ™ÿ´ŸÜÿß" ya "ÿ∫ŸÑÿ∑€å". Jab aisa hota hai, to program ruk jata hai aur error message show hota hai.

`raise` statement ka istemal karte hue, aap jaan bujh kar exception uthaa sakte hain taake specific errors ko handle kiya ja sake. Iska syntax kuch is tarah hota hai:


```python
raise Exception("Error ka paighaam")
```


Yahan, `Exception` aik built-in class hai jo errors ko represent karti hai. Jab `raise` statement execute hota hai, to program mein error paida hota hai aur agar isay handle na kiya jaye, to program crash ho sakta hai.

Aap apni custom exceptions bhi define kar sakte hain jo `Exception` class se inherit karti hain. Yeh approach zyada specific errors ko handle karne mein madadgar hoti hai. ÓàÄciteÓàÇturn0search3ÓàÅ

Aapke provided code mein, agar `data["success"]` false ho ya `"data"` key `data` mein mojood na ho, to `raise Exception("Failed to fetch user data!")` execute hoga. Yeh program ko inform karta hai ke user data hasil karne mein koi masla paish aya hai, aur appropriate error handling ko trigger karta hai. 


-------------
### Haan, bilkul sahi keh rahay ho! üëç  

`raise` ka use hum tab karte hain jab hume khud se ek error (exception) uthana ho. Aur `Exception("Failed to fetch user data!")` likhne ka matlab hai ke jab ye error aye to is message ke sath show ho.  

Matlab agar API se sahi data na aye, to `raise Exception("Failed to fetch user data!")` execute hoga, jo error create karega aur program ko rok dega.  

Agar chaho to `try-except` ka use karke is error ko handle bhi kar sakte ho, taki program crash na ho.

-------------------------
----------------------
------------------
----------------
---------------

## **3. try , exception code breakdowm:**
```python
    try:
        username, country = fetch_userData_from_freeapi()
        print(f"Username is : {username} \nCountry is : {country}")
    except Exception as e:
        print(e)

```
Is code mein `try-except` ka istemal ho raha hai jo errors (exceptions) ko handle karne ke liye hota hai.  

### **Code ka Flow:**
1. `main()` function run hota hai.  
2. `try` block ke andar `fetch_userData_from_freeapi()` function call hota hai.  
3. Yeh function API request bhejta hai aur response ko JSON format mein convert karta hai.  
4. Agar API ka response sahi ho (i.e., `data["success"]` `True` ho aur `"data"` key mojood ho), to username aur country return hoti hai.  
5. Agar response galat ho (ya `"success": False` ho ya `"data"` key mojood na ho), to `raise Exception("Failed to fetch user data!")` execute hota hai.  
6. Jab `raise Exception("Failed to fetch user data!")` execute hota hai, to error uthaya jata hai aur `try` block se seedha `except` block mein jump hoti hai.  

### **Exception Ki Value Kahan Se Aa Rahi Hai?**  
- Jab `fetch_userData_from_freeapi()` function error raise karta hai, to `raise Exception("Failed to fetch user data!")` ke andar jo message diya gaya hai (`"Failed to fetch user data!"`), wahi error ka message ban jata hai.  
- `except Exception as e:` ka `e` variable is error message ko store kar leta hai.  
- Phir `print(e)` statement is message ko print kar deta hai.  

### **Example:**
Agar API ka response kuch aisa ho:  
```json
{
    "success": false,
    "message": "Invalid request"
}
```
To `"success": false` hone ki wajah se `raise Exception("Failed to fetch user data!")` chalega, jo `except` block mein jayega aur `"Failed to fetch user data!"` print hoga.

----------------
Haan, bilkul sahi samjha! üëç  

### **Try-Except Ka Flow:**
1. `try` block ke andar jo bhi code likha hota hai, woh normally execute hota hai.  
2. **Agar koi error (exception) aata hai**, to `try` block us error ko **except block ki taraf bhej deta hai**.  
3. `except` block us error ko **handle karta hai** taki program crash na ho.  
4. `except Exception as e:` likhne ka matlab hai ke jo bhi error aya hoga, woh `e` variable mein store ho jayega.  
5. Phir `print(e)` ya kisi aur tarike se us error ka message show kiya jata hai.  

### **Example:**
 
Agar `try` block mein ye code ho:  

```python
try:
    username, country = fetch_userData_from_freeapi()  # Yeh function API call karega
    print(f"Username is : {username} \nCountry is : {country}")
except Exception as e:
    print(e)
```
To agar API ka response sahi nahi aata (ya `"success": false` hota hai), to `fetch_userData_from_freeapi()` function me **raise Exception("Failed to fetch user data!")** chalega.  

Ye exception `try` block se `except` block mein chali jayegi, aur output hoga:  

```
Failed to fetch user data!
```

### **Conclution:**  
- `try` block code chalata hai.  
- Agar koi **error (exception)** aata hai, to `try` usko `except` block ko bhej deta hai.  
- `except` block error ko **handle** karta hai aur message print karta hai.


Yani `try` block error ko **catch nahi karta**, balki **except block ko bhej deta hai** jo us error ko handle karta hai.
